<mujoco model='planardemo'>
    <compiler inertiafromgeom='true' angle='degree'/>

    <default>
        <joint limited='true' damping='1' armature='0'/>
        <geom contype='1' conaffinity='1' condim='1' rgba='0.8 0.6 0.4 1'
        	margin="0.001" solref=".02 1" solimp=".8 .8 .01" material="geom"/>
    </default>

    <option timestep='0.002' iterations="50" tolerance="1e-10" solver="Newton" jacobian="dense" cone="elliptic" gravity="0 0 0"/>

    <size nstack="1000000"/>

    <visual>
        <map fogstart="3" fogend="5" force="0.1" znear="0.01"/>
        <quality shadowsize="2048" offsamples="8"/>
        <global offwidth="800" offheight="800"/>
    </visual>

    <asset>
        <texture type="skybox" builtin="gradient" width="128" height="128" rgb1=".4 .6 .8" 
            rgb2="0 0 0"/>  
        <texture name="texgeom" type="cube" builtin="flat" mark="cross" width="127" height="1278" 
            rgb1="0.8 0.6 0.4" rgb2="0.8 0.6 0.4" markrgb="1 1 1" random="0.01"/>  
        <texture name="texplane" type="2d" builtin="checker" rgb1=".2 .3 .4" rgb2=".1 0.15 0.2" 
            width="512" height="512"/>  

        <material name='MatPlane' reflectance='0.3' texture="texplane" texrepeat="1 1" texuniform="true"/>
        <material name='geom' texture="texgeom" texuniform="true"/>
    </asset>

    <worldbody>
        <geom name='floor' pos='0 0 0' size='5 5 .125' type='plane' material="MatPlane" condim='3'/>

        <light mode='targetbodycom' target='box' directional='false' diffuse='.8 .8 .8' specular='0.3 0.3 0.3' pos='0 0 4.0' dir='0 0 -1'/>

		<camera name='targeting' pos='1 1 2' mode='targetbodycom' target='box'/>

		<body name="box" pos="0 0 0.2">
		
			<joint name="x" type="slide" range="-0.05 0.125" axis="1 0 0"/>
			<joint name="y" type="slide" range="-0.075 0.075" axis="0 0 1"/>
			<joint name="t" type="hinge" limited="false"  axis="0 1 0" damping="0.1"/>
			
			<geom name="box" type="box" size="0.02 0.02 0.02"/>
			
		</body>

    </worldbody>

</mujoco>
